Workbook

Sheet Cover
A1: Supply Chain Analytics Platform - KPI Workbook
A2: Nationwide (India) distribution network | 12 warehouses | 120 SKUs | 104 weeks | data as of week ending 2026-10-04
A4: Sheet | B4: What it contains | C4: Source
A5: KPI_Dashboard | B5: Headline KPIs, status counts by warehouse, two charts (all live formulas) | C5: Formulas on Stock_Snapshot / Weekly_Trend
A6: Config | B6: Alert thresholds. Change a blue cell and every status in the workbook updates | C6: cfg_thresholds table
A7: Stock_Snapshot | B7: Latest week, every SKU x warehouse: cover, status, value, margin at risk (formulas) | C7: vw_stock_status_latest
A8: Weekly_Trend | B8: 104-week demand, sales, lost sales, stock value, fill rate | C8: vw_inventory_enriched
A9: Warehouse_Scorecard | B9: Fill rate, stock-out rate, turns, on-time inbound POs by warehouse | C9: sp_regional_kpis
A10: Supplier_Scorecard | B10: On-time %, delay, quantity fill, overdue open POs by supplier | C10: vw_supplier_scorecard
A11: Deficit_Alerts | B11: Every deficit line with inbound-PO risk and weekly margin at risk | C11: sp_stock_deficit_alerts
A12: Overdue_POs | B12: Open purchase orders past their promise date, with stock exposure | C12: sp_pipeline_delay_alerts
A13: RCA_Stockouts | B13: Why stock-outs happened: cause summary and warehouse x cause | C13: sp_stockout_root_cause
A14: Excess_Inventory | B14: Excess / above-target stock, carrying cost, expiry risk | C14: sp_excess_inventory_waste
A15: Rebalance | B15: Recommended stock transfers from surplus to deficit warehouses | C15: sp_regional_rebalance
A16: Asset_RCA | B16: Idle, overstretched and ageing assets by warehouse | C16: sp_asset_waste_rca
A19: IMPORTANT - about the data
A20: All data is SIMULATED (generated by scripts/01_generate_data.py) to mirror a real Indian distribution network. Supplier names are fictional. Do not present these figures as results from a real employer.
A23: Colour code: blue text = editable input; black = formula or pasted result.

Sheet KPI_Dashboard
A1: Network KPI dashboard
A2: Live formulas on Stock_Snapshot, Weekly_Trend and the scorecards | as of 2026-10-04
A4: Metric | B4: Value | C4: Definition
A5: Network stock value (INR) | B5: =SUM(Stock_Snapshot!$N$5:$N$1444) | C5: Closing stock x unit cost, latest week
A6: SKU x warehouse lines tracked | B6: =COUNTA(Stock_Snapshot!$D$5:$D$1444)
A7: Lines in STOCKOUT | B7: =COUNTIF(Stock_Snapshot!$K$5:$K$1444,"STOCKOUT") | C7: closing stock = 0 with demand
A8: Lines CRITICAL | B8: =COUNTIF(Stock_Snapshot!$K$5:$K$1444,"CRITICAL") | C8: cover below Config critical threshold
A9: Lines LOW | B9: =COUNTIF(Stock_Snapshot!$K$5:$K$1444,"LOW") | C9: cover below Config low threshold
A10: Lines EXCESS | B10: =COUNTIF(Stock_Snapshot!$K$5:$K$1444,"EXCESS") | C10: cover above Config excess threshold
A11: Deficit lines as % of all lines | B11: =(B7+B8+B9)/B6 | C11: STOCKOUT + CRITICAL + LOW
A12: Weekly margin at risk on deficit lines (INR) | B12: =SUMIFS(Stock_Snapshot!$O$5:$O$1444,Stock_Snapshot!$K$5:$K$1444,"STOCKOUT")+SUMIFS(Stock_Snapshot!$O$5:$O$1444,Stock_Snapshot!$K$5:$K$1444,"CRITICAL")+SUMIFS(Stock_Snapshot!$O$5:$O$1444,Stock_Snapshot!$K$5:$K$1444,"LOW") | C12: avg weekly demand x unit margin
A13: Network fill rate, 104 weeks | B13: =SUM(Weekly_Trend!$C$5:$C$108)/SUM(Weekly_Trend!$B$5:$B$108) | C13: units sold / units demanded
A14: Revenue lost to stock-outs, 104 weeks (INR) | B14: =SUM(Weekly_Trend!$F$5:$F$108) | C14: lost units x selling price
A15: Overdue open POs (>= warn days) | B15: =COUNTA(Overdue_POs!$A$5:$A$75) | C15: pipeline-delay alerts
A16: Value of overdue open POs (INR) | B16: =SUM(Overdue_POs!$O$5:$O$75) | C16: PO value of the above
A19: warehouse_id | B19: warehouse_name | C19: region | D19: stock_value_inr | E19: pct_of_network_stock | F19: STOCKOUT | G19: CRITICAL | H19: LOW | I19: EXCESS | J19: deficit_lines_pct | K19: fill_rate_pct (104 wks)
A20: WH01 | B20: Gurugram DC | C20: North | D20: =SUMIFS(Stock_Snapshot!$N$5:$N$1444,Stock_Snapshot!$A$5:$A$1444,$A20) | E20: =D20/$B$5 | F20: =COUNTIFS(Stock_Snapshot!$A$5:$A$1444,$A20,Stock_Snapshot!$K$5:$K$1444,"STOCKOUT") | G20: =COUNTIFS(Stock_Snapshot!$A$5:$A$1444,$A20,Stock_Snapshot!$K$5:$K$1444,"CRITICAL") | H20: =COUNTIFS(Stock_Snapshot!$A$5:$A$1444,$A20,Stock_Snapshot!$K$5:$K$1444,"LOW") | I20: =COUNTIFS(Stock_Snapshot!$A$5:$A$1444,$A20,Stock_Snapshot!$K$5:$K$1444,"EXCESS") | J20: =(F20+G20+H20)/COUNTIFS(Stock_Snapshot!$A$5:$A$1444,$A20) | K20: =INDEX(Warehouse_Scorecard!$G$5:$G$16,MATCH($A20,Warehouse_Scorecard!$A$5:$A$16,0))
A21: WH02 | B21: Jaipur DC | C21: North | D21: =SUMIFS(Stock_Snapshot!$N$5:$N$1444,Stock_Snapshot!$A$5:$A$1444,$A21) | E21: =D21/$B$5 | F21: =COUNTIFS(Stock_Snapshot!$A$5:$A$1444,$A21,Stock_Snapshot!$K$5:$K$1444,"STOCKOUT") | G21: =COUNTIFS(Stock_Snapshot!$A$5:$A$1444,$A21,Stock_Snapshot!$K$5:$K$1444,"CRITICAL") | H21: =COUNTIFS(Stock_Snapshot!$A$5:$A$1444,$A21,Stock_Snapshot!$K$5:$K$1444,"LOW") | I21: =COUNTIFS(Stock_Snapshot!$A$5:$A$1444,$A21,Stock_Snapshot!$K$5:$K$1444,"EXCESS") | J21: =(F21+G21+H21)/COUNTIFS(Stock_Snapshot!$A$5:$A$1444,$A21) | K21: =INDEX(Warehouse_Scorecard!$G$5:$G$16,MATCH($A21,Warehouse_Scorecard!$A$5:$A$16,0))
A22: WH03 | B22: Lucknow DC | C22: North | D22: =SUMIFS(Stock_Snapshot!$N$5:$N$1444,Stock_Snapshot!$A$5:$A$1444,$A22) | E22: =D22/$B$5 | F22: =COUNTIFS(Stock_Snapshot!$A$5:$A$1444,$A22,Stock_Snapshot!$K$5:$K$1444,"STOCKOUT") | G22: =COUNTIFS(Stock_Snapshot!$A$5:$A$1444,$A22,Stock_Snapshot!$K$5:$K$1444,"CRITICAL") | H22: =COUNTIFS(Stock_Snapshot!$A$5:$A$1444,$A22,Stock_Snapshot!$K$5:$K$1444,"LOW") | I22: =COUNTIFS(Stock_Snapshot!$A$5:$A$1444,$A22,Stock_Snapshot!$K$5:$K$1444,"EXCESS") | J22: =(F22+G22+H22)/COUNTIFS(Stock_Snapshot!$A$5:$A$1444,$A22) | K22: =INDEX(Warehouse_Scorecard!$G$5:$G$16,MATCH($A22,Warehouse_Scorecard!$A$5:$A$16,0))
A23: WH04 | B23: Bhiwandi DC | C23: West | D23: =SUMIFS(Stock_Snapshot!$N$5:$N$1444,Stock_Snapshot!$A$5:$A$1444,$A23) | E23: =D23/$B$5 | F23: =COUNTIFS(Stock_Snapshot!$A$5:$A$1444,$A23,Stock_Snapshot!$K$5:$K$1444,"STOCKOUT") | G23: =COUNTIFS(Stock_Snapshot!$A$5:$A$1444,$A23,Stock_Snapshot!$K$5:$K$1444,"CRITICAL") | H23: =COUNTIFS(Stock_Snapshot!$A$5:$A$1444,$A23,Stock_Snapshot!$K$5:$K$1444,"LOW") | I23: =COUNTIFS(Stock_Snapshot!$A$5:$A$1444,$A23,Stock_Snapshot!$K$5:$K$1444,"EXCESS") | J23: =(F23+G23+H23)/COUNTIFS(Stock_Snapshot!$A$5:$A$1444,$A23) | K23: =INDEX(Warehouse_Scorecard!$G$5:$G$16,MATCH($A23,Warehouse_Scorecard!$A$5:$A$16,0))
A24: WH05 | B24: Pune DC | C24: West | D24: =SUMIFS(Stock_Snapshot!$N$5:$N$1444,Stock_Snapshot!$A$5:$A$1444,$A24) | E24: =D24/$B$5 | F24: =COUNTIFS(Stock_Snapshot!$A$5:$A$1444,$A24,Stock_Snapshot!$K$5:$K$1444,"STOCKOUT") | G24: =COUNTIFS(Stock_Snapshot!$A$5:$A$1444,$A24,Stock_Snapshot!$K$5:$K$1444,"CRITICAL") | H24: =COUNTIFS(Stock_Snapshot!$A$5:$A$1444,$A24,Stock_Snapshot!$K$5:$K$1444,"LOW") | I24: =COUNTIFS(Stock_Snapshot!$A$5:$A$1444,$A24,Stock_Snapshot!$K$5:$K$1444,"EXCESS") | J24: =(F24+G24+H24)/COUNTIFS(Stock_Snapshot!$A$5:$A$1444,$A24) | K24: =INDEX(Warehouse_Scorecard!$G$5:$G$16,MATCH($A24,Warehouse_Scorecard!$A$5:$A$16,0))
A25: WH06 | B25: Ahmedabad DC | C25: West | D25: =SUMIFS(Stock_Snapshot!$N$5:$N$1444,Stock_Snapshot!$A$5:$A$1444,$A25) | E25: =D25/$B$5 | F25: =COUNTIFS(Stock_Snapshot!$A$5:$A$1444,$A25,Stock_Snapshot!$K$5:$K$1444,"STOCKOUT") | G25: =COUNTIFS(Stock_Snapshot!$A$5:$A$1444,$A25,Stock_Snapshot!$K$5:$K$1444,"CRITICAL") | H25: =COUNTIFS(Stock_Snapshot!$A$5:$A$1444,$A25,Stock_Snapshot!$K$5:$K$1444,"LOW") | I25: =COUNTIFS(Stock_Snapshot!$A$5:$A$1444,$A25,Stock_Snapshot!$K$5:$K$1444,"EXCESS") | J25: =(F25+G25+H25)/COUNTIFS(Stock_Snapshot!$A$5:$A$1444,$A25) | K25: =INDEX(Warehouse_Scorecard!$G$5:$G$16,MATCH($A25,Warehouse_Scorecard!$A$5:$A$16,0))
A26: WH07 | B26: Bengaluru DC | C26: South | D26: =SUMIFS(Stock_Snapshot!$N$5:$N$1444,Stock_Snapshot!$A$5:$A$1444,$A26) | E26: =D26/$B$5 | F26: =COUNTIFS(Stock_Snapshot!$A$5:$A$1444,$A26,Stock_Snapshot!$K$5:$K$1444,"STOCKOUT") | G26: =COUNTIFS(Stock_Snapshot!$A$5:$A$1444,$A26,Stock_Snapshot!$K$5:$K$1444,"CRITICAL") | H26: =COUNTIFS(Stock_Snapshot!$A$5:$A$1444,$A26,Stock_Snapshot!$K$5:$K$1444,"LOW") | I26: =COUNTIFS(Stock_Snapshot!$A$5:$A$1444,$A26,Stock_Snapshot!$K$5:$K$1444,"EXCESS") | J26: =(F26+G26+H26)/COUNTIFS(Stock_Snapshot!$A$5:$A$1444,$A26) | K26: =INDEX(Warehouse_Scorecard!$G$5:$G$16,MATCH($A26,Warehouse_Scorecard!$A$5:$A$16,0))
A27: WH08 | B27: Chennai DC | C27: South | D27: =SUMIFS(Stock_Snapshot!$N$5:$N$1444,Stock_Snapshot!$A$5:$A$1444,$A27) | E27: =D27/$B$5 | F27: =COUNTIFS(Stock_Snapshot!$A$5:$A$1444,$A27,Stock_Snapshot!$K$5:$K$1444,"STOCKOUT") | G27: =COUNTIFS(Stock_Snapshot!$A$5:$A$1444,$A27,Stock_Snapshot!$K$5:$K$1444,"CRITICAL") | H27: =COUNTIFS(Stock_Snapshot!$A$5:$A$1444,$A27,Stock_Snapshot!$K$5:$K$1444,"LOW") | I27: =COUNTIFS(Stock_Snapshot!$A$5:$A$1444,$A27,Stock_Snapshot!$K$5:$K$1444,"EXCESS") | J27: =(F27+G27+H27)/COUNTIFS(Stock_Snapshot!$A$5:$A$1444,$A27) | K27: =INDEX(Warehouse_Scorecard!$G$5:$G$16,MATCH($A27,Warehouse_Scorecard!$A$5:$A$16,0))
A28: WH09 | B28: Hyderabad DC | C28: South | D28: =SUMIFS(Stock_Snapshot!$N$5:$N$1444,Stock_Snapshot!$A$5:$A$1444,$A28) | E28: =D28/$B$5 | F28: =COUNTIFS(Stock_Snapshot!$A$5:$A$1444,$A28,Stock_Snapshot!$K$5:$K$1444,"STOCKOUT") | G28: =COUNTIFS(Stock_Snapshot!$A$5:$A$1444,$A28,Stock_Snapshot!$K$5:$K$1444,"CRITICAL") | H28: =COUNTIFS(Stock_Snapshot!$A$5:$A$1444,$A28,Stock_Snapshot!$K$5:$K$1444,"LOW") | I28: =COUNTIFS(Stock_Snapshot!$A$5:$A$1444,$A28,Stock_Snapshot!$K$5:$K$1444,"EXCESS") | J28: =(F28+G28+H28)/COUNTIFS(Stock_Snapshot!$A$5:$A$1444,$A28) | K28: =INDEX(Warehouse_Scorecard!$G$5:$G$16,MATCH($A28,Warehouse_Scorecard!$A$5:$A$16,0))
A29: WH10 | B29: Kolkata DC | C29: East | D29: =SUMIFS(Stock_Snapshot!$N$5:$N$1444,Stock_Snapshot!$A$5:$A$1444,$A29) | E29: =D29/$B$5 | F29: =COUNTIFS(Stock_Snapshot!$A$5:$A$1444,$A29,Stock_Snapshot!$K$5:$K$1444,"STOCKOUT") | G29: =COUNTIFS(Stock_Snapshot!$A$5:$A$1444,$A29,Stock_Snapshot!$K$5:$K$1444,"CRITICAL") | H29: =COUNTIFS(Stock_Snapshot!$A$5:$A$1444,$A29,Stock_Snapshot!$K$5:$K$1444,"LOW") | I29: =COUNTIFS(Stock_Snapshot!$A$5:$A$1444,$A29,Stock_Snapshot!$K$5:$K$1444,"EXCESS") | J29: =(F29+G29+H29)/COUNTIFS(Stock_Snapshot!$A$5:$A$1444,$A29) | K29: =INDEX(Warehouse_Scorecard!$G$5:$G$16,MATCH($A29,Warehouse_Scorecard!$A$5:$A$16,0))
A30: WH11 | B30: Guwahati DC | C30: East | D30: =SUMIFS(Stock_Snapshot!$N$5:$N$1444,Stock_Snapshot!$A$5:$A$1444,$A30) | E30: =D30/$B$5 | F30: =COUNTIFS(Stock_Snapshot!$A$5:$A$1444,$A30,Stock_Snapshot!$K$5:$K$1444,"STOCKOUT") | G30: =COUNTIFS(Stock_Snapshot!$A$5:$A$1444,$A30,Stock_Snapshot!$K$5:$K$1444,"CRITICAL") | H30: =COUNTIFS(Stock_Snapshot!$A$5:$A$1444,$A30,Stock_Snapshot!$K$5:$K$1444,"LOW") | I30: =COUNTIFS(Stock_Snapshot!$A$5:$A$1444,$A30,Stock_Snapshot!$K$5:$K$1444,"EXCESS") | J30: =(F30+G30+H30)/COUNTIFS(Stock_Snapshot!$A$5:$A$1444,$A30) | K30: =INDEX(Warehouse_Scorecard!$G$5:$G$16,MATCH($A30,Warehouse_Scorecard!$A$5:$A$16,0))
A31: WH12 | B31: Nagpur DC | C31: Central | D31: =SUMIFS(Stock_Snapshot!$N$5:$N$1444,Stock_Snapshot!$A$5:$A$1444,$A31) | E31: =D31/$B$5 | F31: =COUNTIFS(Stock_Snapshot!$A$5:$A$1444,$A31,Stock_Snapshot!$K$5:$K$1444,"STOCKOUT") | G31: =COUNTIFS(Stock_Snapshot!$A$5:$A$1444,$A31,Stock_Snapshot!$K$5:$K$1444,"CRITICAL") | H31: =COUNTIFS(Stock_Snapshot!$A$5:$A$1444,$A31,Stock_Snapshot!$K$5:$K$1444,"LOW") | I31: =COUNTIFS(Stock_Snapshot!$A$5:$A$1444,$A31,Stock_Snapshot!$K$5:$K$1444,"EXCESS") | J31: =(F31+G31+H31)/COUNTIFS(Stock_Snapshot!$A$5:$A$1444,$A31) | K31: =INDEX(Warehouse_Scorecard!$G$5:$G$16,MATCH($A31,Warehouse_Scorecard!$A$5:$A$16,0))
A32: NETWORK | D32: =SUM(D20:D31) | F32: =SUM(F20:F31) | G32: =SUM(G20:G31) | H32: =SUM(H20:H31) | I32: =SUM(I20:I31)
A34: Red = more than 30% of the warehouse's SKU lines are in deficit. Blue = holds more than 20% of all network stock value.

Sheet Config
A1: Alert thresholds
A2: Blue cells are inputs. Stock_Snapshot status formulas read rows 5-7.
A4: Parameter | B4: Value | C4: Description
A5: critical_cover_weeks | B5: 0.5 | C5: Closing stock below this many weeks of demand = CRITICAL
A6: low_cover_weeks | B6: 1.5 | C6: Below this = LOW (deficit risk)
A7: excess_cover_weeks | B7: 8 | C7: Above this = EXCESS
A8: obsolete_cover_weeks | B8: 20 | C8: Cover above this many weeks = slow-moving / obsolescence risk
A9: expiry_cover_share | B9: 0.5 | C9: Cover (days) above this share of shelf life = expiry risk
A10: holding_cost_pct_annual | B10: 0.22 | C10: Annual inventory carrying cost as a fraction of stock value
A11: overdue_warn_days | B11: 3 | C11: Open PO this many days past promise = WARNING
A12: overdue_critical_days | B12: 7 | C12: Open PO this many days past promise = CRITICAL
A13: operator_idle_share | B13: 0.25 | C13: Share of operator cost wasted while an asset sits idle
A14: asset_idle_flag_pct | B14: 0.4 | C14: Idle hours / scheduled hours above this = over-provisioned
A15: asset_downtime_flag_pct | B15: 0.07 | C15: Downtime hours / scheduled hours above this = reliability problem
A16: asset_overstretch_util | B16: 0.9 | C16: Run hours / scheduled hours above this = under-provisioned
... A23: capacity_critical_util | B23: 0.9 | C23: Warehouse storage utilisation critical level
A25: Source: project assumptions (typical FMCG DC cover norms); holding cost 22% p.a. is an assumed carrying-cost rate.

Sheet Stock_Snapshot
A1: Stock snapshot - latest week
A2: Week ending 2026-10-04. Cover, status, value and margin-at-risk are formulas driven by the Config sheet.
A4: warehouse_id | B4: warehouse_name | C4: region | D4: sku_id | E4: sku_name | F4: category | G4: abc_class | H4: closing_stock | I4: avg_demand_4w | J4: weeks_of_cover | K4: stock_status | L4: unit_cost_inr | M4: unit_price_inr | N4: stock_value_inr | O4: weekly_margin_at_risk_inr | P4: on_order_units
A5: WH01 | B5: Gurugram DC | C5: North | D5: SKU001 | E5: Atta 5kg | F5: Packaged Staples | G5: A | H5: 7471 | I5: 1058.5 | J5: =IF(I5>0,H5/I5,"") | K5: =IF(I5<=0,"NO DEMAND",IF(H5=0,"STOCKOUT",IF(J5<Config!$B$5,"CRITICAL",IF(J5<Config!$B$6,"LOW",IF(J5>Config!$B$7,"EXCESS","HEALTHY"))))) | L5: 152 | M5: 168 | N5: =H5*L5 | O5: =IF(I5>0,I5*(M5-L5),0) | P5: 0
A6: WH01 | B6: Gurugram DC | C6: North | D6: SKU002 | E6: Basmati Rice 5kg | F6: Packaged Staples | G6: B | H6: 9135 | I6: 1549.25 | J6: =IF(I6>0,H6/I6,"") | K6: =IF(I6<=0,"NO DEMAND",IF(H6=0,"STOCKOUT",IF(J6<Config!$B$5,"CRITICAL",IF(J6<Config!$B$6,"LOW",IF(J6>Config!$B$7,"EXCESS","HEALTHY"))))) | L6: 59 | M6: 66 | N6: =H6*L6 | O6: =IF(I6>0,I6*(M6-L6),0) | P6: 0
A7: WH01 | B7: Gurugram DC | C7: North | D7: SKU003 | E7: Toor Dal 1kg | F7: Packaged Staples | G7: A | H7: 16645 | I7: 2014 | J7: =IF(I7>0,H7/I7,"") | K7: =IF(I7<=0,"NO DEMAND",IF(H7=0,"STOCKOUT",IF(J7<Config!$B$5,"CRITICAL",IF(J7<Config!$B$6,"LOW",IF(J7>Config!$B$7,"EXCESS","HEALTHY"))))) | L7: 61 | M7: 69 | N7: =H7*L7 | O7: =IF(I7>0,I7*(M7-L7),0) | P7: 0
A8: WH01 | B8: Gurugram DC | C8: North | D8: SKU004 | E8: Moong Dal 1kg | F8: Packaged Staples | G8: B | H8: 12370 | I8: 1470.5 | J8: =IF(I8>0,H8/I8,"") | K8: =IF(I8<=0,"NO DEMAND",IF(H8=0,"STOCKOUT",IF(J8<Config!$B$5,"CRITICAL",IF(J8<Config!$B$6,"LOW",IF(J8>Config!$B$7,"EXCESS","HEALTHY"))))) | L8: 80 | M8: 91 | N8: =H8*L8 | O8: =IF(I8>0,I8*(M8-L8),0) | P8: 0
A9: WH01 | B9: Gurugram DC | C9: North | D9: SKU005 | E9: Sunflower Oil 1L | F9: Packaged Staples | G9: A | H9: 11351 | I9: 1755 | J9: =IF(I9>0,H9/I9,"") | K9: =IF(I9<=0,"NO DEMAND",IF(H9=0,"STOCKOUT",IF(J9<Config!$B$5,"CRITICAL",IF(J9<Config!$B$6,"LOW",IF(J9>Config!$B$7,"EXCESS","HEALTHY"))))) | L9: 245 | M9: 273 | N9: =H9*L9 | O9: =IF(I9>0,I9*(M9-L9),0) | P9: 0
A10: WH01 | B10: Gurugram DC | C10: North | D10: SKU006 | E10: Mustard Oil 1L | F10: Packaged Staples | G10: B | H10: 3377 | I10: 636.25 | J10: =IF(I10>0,H10/I10,"") | K10: =IF(I10<=0,"NO DEMAND",IF(H10=0,"STOCKOUT",IF(J10<Config!$B$5,"CRITICAL",IF(J10<Config!$B$6,"LOW",IF(J10>Config!$B$7,"EXCESS","HEALTHY"))))) | L10: 68 | M10: 77 | N10: =H10*L10 | O10: =IF(I10>0,I10*(M10-L10),0) | P10: 0
A11: WH01 | B11: Gurugram DC | C11: North | D11: SKU007 | E11: Sugar 1kg | F11: Packaged Staples | G11: A | H11: 5604 | I11: 1340 | J11: =IF(I11>0,H11/I11,"") | K11: =IF(I11<=0,"NO DEMAND",IF(H11=0,"STOCKOUT",IF(J11<Config!$B$5,"CRITICAL",IF(J11<Config!$B$6,"LOW",IF(J11>Config!$B$7,"EXCESS","HEALTHY"))))) | L11: 129 | M11: 143 | N11: =H11*L11 | O11: =IF(I11>0,I11*(M11-L11),0) | P11: 7332
A12: WH01 | B12: Gurugram DC | C12: North | D12: SKU008 | E12: Iodized Salt 1kg | F12: Packaged Staples | G12: A | H12: 5910 | I12: 1985.5 | J12: =IF(I12>0,H12/I12,"") | K12: =IF(I12<=0,"NO DEMAND",IF(H12=0,"STOCKOUT",IF(J12<Config!$B$5,"CRITICAL",IF(J12<Config!$B$6,"LOW",IF(J12>Config!$B$7,"EXCESS","HEALTHY"))))) | L12: 140 | M12: 156 | N12: =H12*L12 | O12: =IF(I12>0,I12*(M12-L12),0) | P12: 11580
A13: WH01 | B13: Gurugram DC | C13: North | D13: SKU009 | E13: Tea Leaves 500g | F13: Packaged Staples | G13: A | H13: 2565 | I13: 1320.25 | J13: =IF(I13>0,H13/I13,"") | K13: =IF(I13<=0,"NO DEMAND",IF(H13=0,"STOCKOUT",IF(J13<Config!$B$5,"CRITICAL",IF(J13<Config!$B$6,"LOW",IF(J13>Config!$B$7,"EXCESS","HEALTHY"))))) | L13: 103 | M13: 116 | N13: =H13*L13 | O13: =IF(I13>0,I13*(M13-L13),0) | P13: 7860
A14: WH01 | B14: Gurugram DC | C14: North | D14: SKU010 | E14: Poha 500g | F14: Packaged Staples | G14: B | H14: 8566 | I14: 1603.25 | J14: =IF(I14>0,H14/I14,"") | K14: =IF(I14<=0,"NO DEMAND",IF(H14=0,"STOCKOUT",IF(J14<Config!$B$5,"CRITICAL",IF(J14<Config!$B$6,"LOW",IF(J14>Config!$B$7,"EXCESS","HEALTHY"))))) | L14: 40 | M14: 45 | N14: =H14*L14 | O14: =IF(I14>0,I14*(M14-L14),0) | P14: 0
A15: WH01 | B15: Gurugram DC | C15: North | D15: SKU011 | E15: Besan 1kg | F15: Packaged Staples | G15: A | H15: 16642 | I15: 2504.25 | J15: =IF(I15>0,H15/I15,"") | K15: =IF(I15<=0,"NO DEMAND",IF(H15=0,"STOCKOUT",IF(J15<Config!$B$5,"CRITICAL",IF(J15<Config!$B$6,"LOW",IF(J15>Config!$B$7,"EXCESS","HEALTHY"))))) | L15: 110 | M15: 122 | N15: =H15*L15 | O15: =IF(I15>0,I15*(M15-L15),0) | P15: 0
A16: WH01 | B16: Gurugram DC | C16: North | D16: SKU012 | E16: Rajma 1kg | F16: Packaged Staples | G16: B | H16: 1051 | I16: 196 | J16: =IF(I16>0,H16/I16,"") | K16: =IF(I16<=0,"NO DEMAND",IF(H16=0,"STOCKOUT",IF(J16<Config!$B$5,"CRITICAL",IF(J16<Config!$B$6,"LOW",IF(J16>Config!$B$7,"EXCESS","HEALTHY"))))) | L16: 45 | M16: 50 | N16: =H16*L16 | O16: =IF(I16>0,I16*(M16-L16),0) | P16: 0
... A1444: WH12 | B1444: Nagpur DC | C1444: Central | D1444: SKU120 | E1444: Cutter Blades 10pk | F1444: Packaging & Supplies | G1444: C | H1444: 578 | I1444: 196 | J1444: =IF(I1444>0,H1444/I1444,"") | K1444: =IF(I1444<=0,"NO DEMAND",IF(H1444=0,"STOCKOUT",IF(J1444<Config!$B$5,"CRITICAL",IF(J1444<Config!$B$6,"LOW",IF(J1444>Config!$B$7,"EXCESS","HEALTHY"))))) | L1444: 30 | M1444: 35 | N1444: =H1444*L1444 | O1444: =IF(I1444>0,I1444*(M1444-L1444),0) | P1444: 0

Sheet Weekly_Trend
A1: Weekly network trend
A2: Aggregated from vw_inventory_enriched. Fill rate is a formula.
A4: week_start | B4: demand_units | C4: units_sold | D4: lost_units | E4: stock_value_inr | F4: lost_revenue_inr | G4: fill_rate
A5: 45572 | B5: 682736 | C5: 682736 | D5: 0 | E5: 412667212 | F5: 0 | G5: =IF(B5>0,C5/B5,0)
A6: 45579 | B6: 762133 | C6: 762133 | D6: 0 | E6: 316192828 | F6: 0 | G6: =IF(B6>0,C6/B6,0)
A7: 45586 | B7: 779920 | C7: 779395 | D7: 525 | E7: 276126414 | F7: 385393 | G7: =IF(B7>0,C7/B7,0)
A8: 45593 | B8: 726058 | C8: 715526 | D8: 10532 | E8: 256569770 | F8: 2653728 | G8: =IF(B8>0,C8/B8,0)
A9: 45600 | B9: 623882 | C9: 606490 | D9: 17392 | E9: 297843689 | F9: 4000447 | G9: =IF(B9>0,C9/B9,0)
A10: 45607 | B10: 604424 | C10: 589960 | D10: 14464 | E10: 309070240 | F10: 4461438 | G10: =IF(B10>0,C10/B10,0)
A11: 45614 | B11: 610896 | C11: 597752 | D11: 13144 | E11: 332248202 | F11: 3356268 | G11: =IF(B11>0,C11/B11,0)
A12: 45621 | B12: 605468 | C12: 594124 | D12: 11344 | E12: 335990067 | F12: 2170706 | G12: =IF(B12>0,C12/B12,0)
A13: 45628 | B13: 591034 | C13: 581939 | D13: 9095 | E13: 363163391 | F13: 1294619 | G13: =IF(B13>0,C13/B13,0)
A14: 45635 | B14: 584396 | C14: 570781 | D14: 13615 | E14: 358232373 | F14: 1324180 | G14: =IF(B14>0,C14/B14,0)
A15: 45642 | B15: 578530 | C15: 564142 | D15: 14388 | E15: 344755293 | F15: 1780678 | G15: =IF(B15>0,C15/B15,0)
A16: 45649 | B16: 592142 | C16: 580962 | D16: 11180 | E16: 325087776 | F16: 2024544 | G16: =IF(B16>0,C16/B16,0)
... A108: 46293 | B108: 737507 | C108: 709903 | D108: 27604 | E108: 275416031 | F108: 7254024 | G108: =IF(B108>0,C108/B108,0)

Sheet Warehouse_Scorecard
A1: Warehouse scorecard - 104 weeks
A2: Source: sp_regional_kpis. Totals row and lost-revenue share are formulas.
A4: warehouse_id | B4: warehouse_name | C4: region | D4: demand_units | E4: units_sold | F4: lost_units | G4: fill_rate_pct | H4: stockout_rate_pct | I4: avg_inventory_value_inr | J4: inventory_turns_annualised | K4: avg_weeks_of_cover | L4: lost_revenue_inr | M4: lost_margin_inr | N4: inbound_on_time_pct | O4: inbound_avg_days_vs_promise | P4: inbound_qty_fill_pct | Q4: lost_revenue_share_pct
A5: WH01 | B5: Gurugram DC | C5: North | D5: 6983595 | E5: 6979590 | F5: 4005 | G5: 99.94 | H5: 0.16 | I5: 51520500 | J5: 7.93 | K5: 6.7 | L5: 1751269 | M5: 392343 | N5: 71.6 | O5: 1.81 | P5: 98.7 | Q5: =100*L5/L$17
A6: WH02 | B6: Jaipur DC | C6: North | D6: 3369668 | E6: 3314057 | F6: 55611 | G6: 98.35 | H6: 3.85 | I6: 12041668 | J6: 15.19 | K6: 4.36 | L6: 13084798 | M6: 2644377 | N6: 72.8 | O6: 1.81 | P6: 98.7 | Q6: =100*L6/L$17
A7: WH03 | B7: Lucknow DC | C7: North | D7: 4010930 | E7: 3935606 | F7: 75324 | G7: 98.12 | H7: 4.01 | I7: 13104455 | J7: 16.64 | K7: 3.96 | L7: 13970652 | M7: 2827624 | N7: 73.2 | O7: 1.62 | P7: 99 | Q7: =100*L7/L$17
A8: WH04 | B8: Bhiwandi DC | C8: West | D8: 10306920 | E8: 10304251 | F8: 2669 | G8: 99.97 | H8: 0.11 | I8: 77653585 | J8: 7.59 | K8: 6.99 | L8: 2524800 | M8: 525714 | N8: 71 | O8: 1.83 | P8: 98.3 | Q8: =100*L8/L$17
A9: WH05 | B9: Pune DC | C9: West | D9: 5224918 | E9: 5168843 | F9: 56075 | G9: 98.93 | H9: 2.72 | I9: 18559718 | J9: 16.01 | K9: 3.69 | L9: 11815857 | M9: 2311615 | N9: 72.3 | O9: 1.71 | P9: 98.8 | Q9: =100*L9/L$17
A10: WH06 | B10: Ahmedabad DC | C10: West | D10: 5798562 | E10: 5677080 | F10: 121482 | G10: 97.9 | H10: 4.6 | I10: 17238670 | J10: 18.93 | K10: 3.08 | L10: 33955993 | M10: 7298254 | N10: 70.8 | O10: 1.74 | P10: 98.5 | Q10: =100*L10/L$17
A11: WH07 | B11: Bengaluru DC | C11: South | D11: 8272515 | E11: 8126793 | F11: 145722 | G11: 98.24 | H11: 4.41 | I11: 23647871 | J11: 18.59 | K11: 2.91 | L11: 30057884 | M11: 5857465 | N11: 73.5 | O11: 1.66 | P11: 98.7 | Q11: =100*L11/L$17
A12: WH08 | B12: Chennai DC | C12: South | D12: 6876535 | E12: 6129663 | F12: 746872 | G12: 89.14 | H12: 21.19 | I12: 9005020 | J12: 36.17 | K12: 1.57 | L12: 143947020 | M12: 28469474 | N12: 71.1 | O12: 1.69 | P12: 98.6 | Q12: =100*L12/L$17
A13: WH09 | B13: Hyderabad DC | C13: South | D13: 6973111 | E13: 6836275 | F13: 136836 | G13: 98.04 | H13: 4.45 | I13: 20624781 | J13: 18.07 | K13: 3.06 | L13: 30561561 | M13: 6381833 | N13: 72.6 | O13: 1.73 | P13: 98.5 | Q13: =100*L13/L$17
A14: WH10 | B14: Kolkata DC | C14: East | D14: 6535161 | E14: 6323411 | F14: 211750 | G14: 96.76 | H14: 7.4 | I14: 16346237 | J14: 21.18 | K14: 2.54 | L14: 41054717 | M14: 8190307 | N14: 70.4 | O14: 1.81 | P14: 98.5 | Q14: =100*L14/L$17
A15: WH11 | B15: Guwahati DC | C15: East | D15: 2676879 | E15: 2351965 | F15: 324914 | G15: 87.86 | H15: 17.08 | I15: 7128069 | J15: 18.56 | K15: 4.03 | L15: 59130340 | M15: 11553298 | N15: 62.3 | O15: 2.32 | P15: 98.9 | Q15: =100*L15/L$17
A16: WH12 | B16: Nagpur DC | C16: Central | D16: 3198410 | E16: 3149001 | F16: 49409 | G16: 98.46 | H16: 3.57 | I16: 11411256 | J16: 15.89 | K16: 4.3 | L16: 14213493 | M16: 2770377 | N16: 72.9 | O16: 1.65 | P16: 98.5 | Q16: =100*L16/L$17
A17: NETWORK | D17: =SUM(D5:D16) | E17: =SUM(E5:E16) | F17: =SUM(F5:F16) | G17: =100*E17/D17 | I17: =SUM(I5:I16) | L17: =SUM(L5:L16) | M17: =SUM(M5:M16)

Sheet Supplier_Scorecard
A1: Supplier scorecard
A2: Source: vw_supplier_scorecard (sorted worst on-time first). Red = on-time below 60%.
A4: supplier_id | B4: supplier_name | C4: category | D4: supplier_tier | E4: po_count | F4: received_pos | G4: on_time_pct | H4: avg_days_vs_promise | I4: avg_days_late_when_late | J4: qty_fill_pct | K4: open_pos | L4: overdue_open_pos | M4: overdue_open_value_inr | N4: total_po_value_inr
A5: SUP17 | B5: ConnectPro Gadgets | C5: Electronics Accessories | D5: Tier 3 | E5: 1145 | F5: 1099 | G5: 38.4 | H5: 5.98 | I5: 9.71 | J5: 96.6 | K5: 46 | L5: 19 | M5: 9027725 | N5: 651142557
A6: SUP03 | B6: Kisan Mill Traders | C6: Packaged Staples | D6: Tier 3 | E6: 1138 | F6: 1114 | G6: 44.5 | H6: 4.38 | I6: 7.89 | J6: 97.4 | K6: 24 | L6: 12 | M6: 6188270 | N6: 404712883
A7: SUP12 | B7: PureSkin Personal Care | C7: Personal Care | D7: Tier 3 | E7: 2123 | F7: 2073 | G7: 47.8 | H7: 4.71 | I7: 9.02 | J7: 97.3 | K7: 50 | L7: 22 | M7: 3569159 | N7: 322801595
A8: SUP22 | B8: SafeShip Packaging | C8: Packaging & Supplies | D8: Tier 3 | E8: 2178 | F8: 2105 | G8: 50 | H8: 3.8 | I8: 7.6 | J8: 97.3 | K8: 73 | L8: 21 | M8: 3647099 | N8: 325429969
A9: SUP20 | B9: WellSpring OTC Pvt Ltd | C9: OTC Pharma & Wellness | D9: Tier 2 | E9: 1281 | F9: 1257 | G9: 64.3 | H9: 2.04 | I9: 5.71 | J9: 98.2 | K9: 24 | L9: 0 | M9: 0 | N9: 109068053
A10: SUP15 | B10: TechNest Accessories | C10: Electronics Accessories | D10: Tier 2 | E10: 466 | F10: 451 | G10: 67.8 | H10: 1.88 | I10: 5.84 | J10: 97.9 | K10: 15 | L10: 0 | M10: 0 | N10: 410859259
A11: SUP06 | B11: Sunrise Fruit Drinks | C11: Beverages | D11: Tier 2 | E11: 1686 | F11: 1667 | G11: 68 | H11: 1.6 | I11: 5.01 | J11: 98.4 | K11: 19 | L11: 3 | M11: 1147739 | N11: 540267204
A12: SUP11 | B12: Ayur Beauty Labs | C12: Personal Care | D12: Tier 2 | E12: 1013 | F12: 994 | G12: 71.4 | H12: 1.54 | I12: 5.4 | J12: 98.2 | K12: 19 | L12: 1 | M12: 36336 | N12: 275332372
A13: SUP19 | B13: MediTrust Healthcare | C13: OTC Pharma & Wellness | D13: Tier 2 | E13: 1293 | F13: 1255 | G13: 72.7 | H13: 1.37 | I13: 5.04 | J13: 98.9 | K13: 38 | L13: 2 | M13: 160008 | N13: 163033781
A14: SUP08 | B14: Mithaiwala Confectionery | C14: Snacks & Confectionery | D14: Tier 2 | E14: 1605 | F14: 1587 | G14: 73 | H14: 1.32 | I14: 4.9 | J14: 98.6 | K14: 18 | L14: 4 | M14: 617854 | N14: 264169335
A15: SUP05 | B15: Himalayan Spring Bottlers | C15: Beverages | D15: Tier 2 | E15: 1008 | F15: 992 | G15: 75.5 | H15: 1.11 | I15: 4.53 | J15: 99 | K15: 16 | L15: 1 | M15: 52129 | N15: 140296566
A16: SUP02 | B16: Annapurna Staples Pvt Ltd | C16: Packaged Staples | D16: Tier 2 | E16: 1930 | F16: 1897 | G16: 76.2 | H16: 1.17 | I16: 4.89 | J16: 98.6 | K16: 33 | L16: 7 | M16: 4175890 | N16: 646676807
... A26: SUP01 | B26: Shree Ganesh Agro Foods | C26: Packaged Staples | D26: Tier 1 | E26: 1152 | F26: 1140 | G26: 87.4 | H26: 0.49 | I26: 3.9 | J26: 99 | K26: 12 | L26: 2 | M26: 286543 | N26: 374234891

Sheet Deficit_Alerts
A1: Stock-deficit alerts
A2: Source: sp_stock_deficit_alerts. Sorted STOCKOUT > CRITICAL > LOW, then margin at risk.
A4: warehouse_id | B4: warehouse_name | C4: region | D4: sku_id | E4: sku_name | F4: category | G4: abc_class | H4: stock_status | I4: weeks_of_cover | J4: closing_stock | K4: avg_weekly_demand | L4: inbound_open_qty | M4: next_po_id | N4: next_promised_date | O4: inbound_risk | P4: weekly_margin_at_risk_inr
A5: WH06 | B5: Ahmedabad DC | C5: West | D5: SKU080 | E5: TWS Earbuds | F5: Electronics Accessories | G5: A | H5: STOCKOUT | I5: 0 | J5: 0 | K5: 382.8 | L5: 2620 | M5: PO0030386 | N5: 2026-09-21 | O5: INBOUND OVERDUE | P5: 271370
A6: WH07 | B6: Bengaluru DC | C6: South | D6: SKU089 | E6: USB Keyboard | F6: Electronics Accessories | G6: A | H6: STOCKOUT | I6: 0 | J6: 0 | K6: 292.3 | L6: 1090 | M6: PO0030901 | N6: 2026-09-25 | O6: INBOUND OVERDUE | P6: 164537
A7: WH08 | B7: Chennai DC | C7: South | D7: SKU080 | E7: TWS Earbuds | F7: Electronics Accessories | G7: A | H7: STOCKOUT | I7: 0 | J7: 0 | K7: 208.8 | L7: 990 | M7: PO0030118 | N7: 2026-09-17 | O7: INBOUND OVERDUE | P7: 148004
A8: WH08 | B8: Chennai DC | C8: South | D8: SKU079 | E8: Wired Earphones | F8: Electronics Accessories | G8: A | H8: STOCKOUT | I8: 0 | J8: 0 | K8: 217.5 | L8: 970 | M8: PO0030580 | N8: 2026-10-01 | O8: INBOUND OVERDUE | P8: 65685
A9: WH08 | B9: Chennai DC | C9: South | D9: SKU056 | E9: Sunscreen 50g | F9: Personal Care | G9: A | H9: STOCKOUT | I9: 0 | J9: 0 | K9: 391.8 | L9: 972 | M9: PO0031926 | N9: 2026-10-11 | O9: GAP BEFORE ARRIVAL | P9: 45835
A10: WH11 | B10: Guwahati DC | C10: East | D10: SKU087 | E10: SD Card 64GB | F10: Electronics Accessories | G10: A | H10: STOCKOUT | I10: 0 | J10: 0 | K10: 91 | L10: 480 | M10: PO0031312 | N10: 2026-10-12 | O10: GAP BEFORE ARRIVAL | P10: 39130
A11: WH11 | B11: Guwahati DC | C11: East | D11: SKU079 | E11: Wired Earphones | F11: Electronics Accessories | G11: A | H11: STOCKOUT | I11: 0 | J11: 0 | K11: 124.8 | L11: 420 | M11: PO0031641 | N11: 2026-10-28 | O11: GAP BEFORE ARRIVAL | P11: 37675
A12: WH08 | B12: Chennai DC | C12: South | D12: SKU059 | E12: Lip Balm | F12: Personal Care | G12: B | H12: STOCKOUT | I12: 0 | J12: 0 | K12: 773.3 | L12: 1668 | M12: PO0031927 | N12: 2026-10-09 | O12: GAP BEFORE ARRIVAL | P12: 37116
A13: WH10 | B13: Kolkata DC | C13: East | D13: SKU061 | E13: Detergent Powder 2kg | F13: Home Care | G13: B | H13: STOCKOUT | I13: 0 | J13: 0 | K13: 1206.8 | L13: 3492 | M13: PO0031456 | N13: 2026-10-05 | O13: GAP BEFORE ARRIVAL | P13: 33789
A14: WH08 | B14: Chennai DC | C14: South | D14: SKU111 | E14: Shipping Labels 1000 | F14: Packaging & Supplies | G14: A | H14: STOCKOUT | I14: 0 | J14: 0 | K14: 241.8 | L14: 1180 | M14: PO0030926 | N14: 2026-10-01 | O14: INBOUND OVERDUE | P14: 29977
A15: WH06 | B15: Ahmedabad DC | C15: West | D15: SKU034 | E15: Cream Biscuits 120g | F15: Snacks & Confectionery | G15: B | H15: STOCKOUT | I15: 0 | J15: 0 | K15: 2205.3 | L15: 7272 | M15: PO0031553 | N15: 2026-10-01 | O15: INBOUND OVERDUE | P15: 26463
A16: WH06 | B16: Ahmedabad DC | C16: West | D16: SKU033 | E16: Glucose Biscuits 300g | F16: Snacks & Confectionery | G16: A | H16: STOCKOUT | I16: 0 | J16: 0 | K16: 1055.3 | L16: 2964 | M16: PO0031892 | N16: 2026-10-05 | O16: GAP BEFORE ARRIVAL | P16: 26381
... A66: WH11 | B66: Guwahati DC | C66: East | D66: SKU022 | E66: Iced Tea 500ml | F66: Beverages | G66: A | H66: STOCKOUT | I66: 0 | J66: 0 | K66: 786.3 | L66: 2712 | M66: PO0031466 | N66: 2026-10-05 | O66: GAP BEFORE ARRIVAL | P66: 8649
A67: WH08 | B67: Chennai DC | C67: South | D67: SKU020 | E67: Energy Drink 250ml | F67: Beverages | G67: B | H67: STOCKOUT | I67: 0 | J67: 0 | K67: 2120.3 | L67: 0 | O67: NO INBOUND PO | P67: 8481
A68: WH08 | B68: Chennai DC | C68: South | D68: SKU047 | E68: Soap 4-pack | F68: Personal Care | G68: C | H68: STOCKOUT | I68: 0 | J68: 0 | K68: 834.3 | L68: 1476 | M68: PO0031428 | N68: 2026-10-02 | O68: INBOUND OVERDUE | P68: 8343
A69: WH08 | B69: Chennai DC | C69: South | D69: SKU105 | E69: Face Masks 50pk | F69: OTC Pharma & Wellness | G69: C | H69: STOCKOUT | I69: 0 | J69: 0 | K69: 286.8 | L69: 792 | M69: PO0031601 | N69: 2026-10-06 | O69: GAP BEFORE ARRIVAL | P69: 8316
A70: WH07 | B70: Bengaluru DC | C70: South | D70: SKU075 | E70: Naphthalene Balls 200g | F70: Home Care | G70: C | H70: STOCKOUT | I70: 0 | J70: 0 | K70: 739.3 | L70: 3324 | M70: PO0031574 | N70: 2026-10-06 | O70: GAP BEFORE ARRIVAL | P70: 8132
A71: WH02 | B71: Jaipur DC | C71: North | D71: SKU019 | E71: Packaged Water 1L | F71: Beverages | G71: A | H71: STOCKOUT | I71: 0 | J71: 0 | K71: 736.8 | L71: 2520 | M71: PO0031341 | N71: 2026-10-01 | O71: INBOUND OVERDUE | P71: 8104
A72: WH06 | B72: Ahmedabad DC | C72: West | D72: SKU063 | E72: Floor Cleaner 1L | F72: Home Care | G72: C | H72: STOCKOUT | I72: 0 | J72: 0 | K72: 663.3 | L72: 2448 | M72: PO0031394 | N72: 2026-10-02 | O72: INBOUND OVERDUE | P72: 7959
A73: WH08 | B73: Chennai DC | C73: South | D73: SKU103 | E73: Zinc Tablets 20s | F73: OTC Pharma & Wellness | G73: C | H73: STOCKOUT | I73: 0 | J73: 0 | K73: 164 | L73: 636 | M73: PO0031600 | N73: 2026-10-05 | O73: GAP BEFORE ARRIVAL | P73: 7708
A74: WH06 | B74: Ahmedabad DC | C74: West | D74: SKU045 | E74: Candy Pack 150g | F74: Snacks & Confectionery | G74: C | H74: STOCKOUT | I74: 0 | J74: 0 | K74: 1540.3 | L74: 5316 | M74: PO0031392 | N74: 2026-10-02 | O74: INBOUND OVERDUE | P74: 7701
A75: WH02 | B75: Jaipur DC | C75: North | D75: SKU065 | E75: Glass Cleaner 500ml | F75: Home Care | G75: B | H75: STOCKOUT | I75: 0 | J75: 0 | K75: 378 | L75: 1512 | M75: PO0031001 | N75: 2026-09-29 | O75: INBOUND OVERDUE | P75: 7560
A76: WH08 | B76: Chennai DC | C76: South | D76: SKU003 | E76: Toor Dal 1kg | F76: Packaged Staples | G76: A | H76: STOCKOUT | I76: 0 | J76: 0 | K76: 921 | L76: 2340 | M76: PO0031757 | N76: 2026-10-09 | O76: GAP BEFORE ARRIVAL | P76: 7368
A77: WH08 | B77: Chennai DC | C77: South | D77: SKU001 | E77: Atta 5kg | F77: Packaged Staples | G77: A | H77: STOCKOUT | I77: 0 | J77: 0 | K77: 442.3 | L77: 1716 | M77: PO0031756 | N77: 2026-10-11 | O77: GAP BEFORE ARRIVAL | P77: 7076
A78: WH02 | B78: Jaipur DC | C78: North | D78: SKU046 | E78: Shampoo 340ml | F78: Personal Care | G78: C | H78: STOCKOUT | I78: 0 | J78: 0 | K78: 425.5 | L78: 1476 | M78: PO0031343 | N78: 2026-10-03 | O78: INBOUND OVERDUE | P78: 6808
A79: WH11 | B79: Guwahati DC | C79: East | D79: SKU055 | E79: Talc 300g | F79: Personal Care | G79: B | H79: STOCKOUT | I79: 0 | J79: 0 | K79: 291.8 | L79: 1272 | M79: PO0031638 | N79: 2026-10-05 | O79: GAP BEFORE ARRIVAL | P79: 6710
... A130: WH08 | B130: Chennai DC | C130: South | D130: SKU074 | E130: Matchbox 10pk | F130: Home Care | G130: A | H130: CRITICAL | I130: 0.28 | J130: 205 | K130: 741 | L130: 1284 | M130: PO0031769 | N130: 2026-10-12 | O130: GAP BEFORE ARRIVAL | P130: 42978
A131: WH08 | B131: Chennai DC | C131: South | D131: SKU067 | E131: Mosquito Coil 10pk | F131: Home Care | G131: A | H131: CRITICAL | I131: 0.46 | J131: 267 | K131: 585 | L131: 0 | O131: NO INBOUND PO | P131: 33345
A132: WH07 | B132: Bengaluru DC | C132: South | D132: SKU074 | E132: Matchbox 10pk | F132: Home Care | G132: A | H132: CRITICAL | I132: 0.42 | J132: 206 | K132: 485 | L132: 1848 | M132: PO0031573 | N132: 2026-10-06 | O132: COVERED BY INBOUND | P132: 28130
A133: WH07 | B133: Bengaluru DC | C133: South | D133: SKU082 | E133: Phone Case | F133: Electronics Accessories | G133: B | H133: CRITICAL | I133: 0.2 | J133: 32 | K133: 162.5 | L133: 1340 | M133: PO0030723 | N133: 2026-10-04 | O133: COVERED BY INBOUND | P133: 27625
A134: WH08 | B134: Chennai DC | C134: South | D134: SKU085 | E134: Extension Board 4-socket | F134: Electronics Accessories | G134: B | H134: CRITICAL | I134: 0.16 | J134: 44 | K134: 269.3 | L134: 800 | M134: PO0031930 | N134: 2026-10-20 | O134: GAP BEFORE ARRIVAL | P134: 25579
A135: WH06 | B135: Ahmedabad DC | C135: West | D135: SKU040 | E135: Wafers 75g | F135: Snacks & Confectionery | G135: A | H135: CRITICAL | I135: 0.3 | J135: 389 | K135: 1313.5 | L135: 3624 | M135: PO0031555 | N135: 2026-09-30 | O135: INBOUND OVERDUE | P135: 24957
A136: WH04 | B136: Bhiwandi DC | C136: West | D136: SKU052 | E136: Deodorant 150ml | F136: Personal Care | G136: B | H136: CRITICAL | I136: 0.05 | J136: 28 | K136: 535.3 | L136: 3132 | M136: PO0030680 | N136: 2026-09-19 | O136: INBOUND OVERDUE | P136: 24622
A137: WH08 | B137: Chennai DC | C137: South | D137: SKU041 | E137: Mathri 250g | F137: Snacks & Confectionery | G137: A | H137: CRITICAL | I137: 0.22 | J137: 185 | K137: 854.8 | L137: 1728 | M137: PO0031767 | N137: 2026-10-10 | O137: GAP BEFORE ARRIVAL | P137: 21369
A138: WH10 | B138: Kolkata DC | C138: East | D138: SKU007 | E138: Sugar 1kg | F138: Packaged Staples | G138: A | H138: CRITICAL | I138: 0.08 | J138: 111 | K138: 1469.3 | L138: 4176 | M138: PO0031617 | N138: 2026-10-05 | O138: GAP BEFORE ARRIVAL | P138: 20570
A139: WH10 | B139: Kolkata DC | C139: East | D139: SKU085 | E139: Extension Board 4-socket | F139: Electronics Accessories | G139: B | H139: CRITICAL | I139: 0.2 | J139: 40 | K139: 202.8 | L139: 780 | M139: PO0031302 | N139: 2026-10-06 | O139: GAP BEFORE ARRIVAL | P139: 19261
A140: WH07 | B140: Bengaluru DC | C140: South | D140: SKU052 | E140: Deodorant 150ml | F140: Personal Care | G140: B | H140: CRITICAL | I140: 0.31 | J140: 121 | K140: 391.5 | L140: 2112 | M140: PO0031248 | N140: 2026-09-27 | O140: INBOUND OVERDUE | P140: 18009
...

Sheet Overdue_POs
A1: Pipeline delays - open POs past promise date
A2: Source: sp_pipeline_delay_alerts (>= warn threshold). Most overdue first.
A4: po_id | B4: warehouse_id | C4: warehouse_name | D4: region | E4: sku_id | F4: sku_name | G4: category | H4: supplier_id | I4: supplier_name | J4: supplier_tier | K4: order_date | L4: promised_date | M4: days_overdue | N4: ordered_qty | O4: po_value_inr | P4: closing_stock_now | Q4: weeks_of_cover_now | R4: stock_status | S4: severity | T4: exposure
A5: PO0030118 | B5: WH08 | C5: Chennai DC | D5: South | E5: SKU080 | F5: TWS Earbuds | G5: Electronics Accessories | H5: SUP17 | I5: ConnectPro Gadgets | J5: Tier 3 | K5: 2026-08-24 | L5: 2026-09-17 | M5: 17 | N5: 540 | O5: 1185295 | P5: 0 | Q5: 0 | R5: STOCKOUT | S5: CRITICAL | T5: STOCK-OUT EXPOSURE
A6: PO0030033 | B6: WH01 | C6: Gurugram DC | D6: North | E6: SKU114 | F6: Cable Ties 100pk | G6: Packaging & Supplies | H6: SUP22 | I6: SafeShip Packaging | J6: Tier 3 | K6: 2026-08-24 | L6: 2026-09-17 | M6: 17 | N6: 2760 | O6: 183071 | P6: 1266 | Q6: 2.7 | R6: HEALTHY | S6: CRITICAL | T6: NO IMMEDIATE EXPOSURE
A7: PO0030252 | B7: WH06 | C7: Ahmedabad DC | D7: West | E7: SKU078 | F7: Power Bank 10000mAh | G7: Electronics Accessories | H7: SUP17 | I7: ConnectPro Gadgets | J7: Tier 3 | K7: 2026-08-25 | L7: 2026-09-17 | M7: 17 | N7: 410 | O7: 144833 | P7: 0 | Q7: 0 | R7: STOCKOUT | S7: CRITICAL | T7: STOCK-OUT EXPOSURE
A8: PO0030704 | B8: WH06 | C8: Ahmedabad DC | D8: West | E8: SKU059 | F8: Lip Balm | G8: Personal Care | H8: SUP12 | I8: PureSkin Personal Care | J8: Tier 3 | K8: 2026-09-07 | L8: 2026-09-17 | M8: 17 | N8: 828 | O8: 123918 | P8: 0 | Q8: 0 | R8: STOCKOUT | S8: CRITICAL | T8: STOCK-OUT EXPOSURE
A9: PO0030235 | B9: WH05 | C9: Pune DC | D9: West | E9: SKU082 | F9: Phone Case | G9: Electronics Accessories | H9: SUP17 | I9: ConnectPro Gadgets | J9: Tier 3 | K9: 2026-08-25 | L9: 2026-09-18 | M9: 16 | N9: 470 | O9: 304936 | P9: 13 | Q9: 0.13 | R9: CRITICAL | S9: CRITICAL | T9: STOCK-OUT EXPOSURE
A10: PO0030680 | B10: WH04 | C10: Bhiwandi DC | D10: West | E10: SKU052 | F10: Deodorant 150ml | G10: Personal Care | H10: SUP12 | I10: PureSkin Personal Care | J10: Tier 3 | K10: 2026-09-07 | L10: 2026-09-19 | M10: 15 | N10: 3132 | O10: 407692 | P10: 28 | Q10: 0.05 | R10: CRITICAL | S10: CRITICAL | T10: STOCK-OUT EXPOSURE
A11: PO0030386 | B11: WH06 | C11: Ahmedabad DC | D11: West | E11: SKU080 | F11: TWS Earbuds | G11: Electronics Accessories | H11: SUP17 | I11: ConnectPro Gadgets | J11: Tier 3 | K11: 2026-08-31 | L11: 2026-09-21 | M11: 13 | N11: 1260 | O11: 2857768 | P11: 0 | Q11: 0 | R11: STOCKOUT | S11: CRITICAL | T11: STOCK-OUT EXPOSURE
A12: PO0031008 | B12: WH03 | C12: Lucknow DC | D12: North | E12: SKU007 | F12: Sugar 1kg | G12: Packaged Staples | H12: SUP02 | I12: Annapurna Staples Pvt Ltd | J12: Tier 2 | K12: 2026-09-14 | L12: 2026-09-24 | M12: 10 | N12: 4284 | O12: 555678 | P12: 0 | Q12: 0 | R12: STOCKOUT | S12: CRITICAL | T12: STOCK-OUT EXPOSURE
A13: PO0031070 | B13: WH06 | C13: Ahmedabad DC | D13: West | E13: SKU055 | F13: Talc 300g | G13: Personal Care | H13: SUP12 | I13: PureSkin Personal Care | J13: Tier 3 | K13: 2026-09-14 | L13: 2026-09-24 | M13: 10 | N13: 1644 | O13: 126966 | P13: 0 | Q13: 0 | R13: STOCKOUT | S13: CRITICAL | T13: STOCK-OUT EXPOSURE
A14: PO0030901 | B14: WH07 | C14: Bengaluru DC | D14: South | E14: SKU089 | F14: USB Keyboard | G14: Electronics Accessories | H14: SUP16 | I14: VoltEdge Electronics | J14: Tier 1 | K14: 2026-09-08 | L14: 2026-09-25 | M14: 9 | N14: 1090 | O14: 2384746 | P14: 0 | Q14: 0 | R14: STOCKOUT | S14: CRITICAL | T14: STOCK-OUT EXPOSURE
A15: PO0031277 | B15: WH09 | C15: Hyderabad DC | D15: South | E15: SKU011 | F15: Besan 1kg | G15: Packaged Staples | H15: SUP03 | I15: Kisan Mill Traders | J15: Tier 3 | K15: 2026-09-15 | L15: 2026-09-25 | M15: 9 | N15: 3936 | O15: 432684 | P15: 0 | Q15: 0 | R15: STOCKOUT | S15: CRITICAL | T15: STOCK-OUT EXPOSURE
A16: PO0031010 | B16: WH03 | C16: Lucknow DC | D16: North | E16: SKU013 | F16: Jaggery 1kg | G16: Packaged Staples | H16: SUP03 | I16: Kisan Mill Traders | J16: Tier 3 | K16: 2026-09-14 | L16: 2026-09-25 | M16: 9 | N16: 3156 | O16: 403526 | P16: 0 | Q16: 0 | R16: STOCKOUT | S16: CRITICAL | T16: STOCK-OUT EXPOSURE
... A75: PO0031314 | B75: WH11 | C75: Guwahati DC | D75: East | E75: SKU116 | F75: Pallet Wrap Hand | G75: Packaging & Supplies | H75: SUP22 | I75: SafeShip Packaging | J75: Tier 3 | K75: 2026-09-15 | L75: 2026-10-01 | M75: 3 | N75: 240 | O75: 9631 | P75: 0 | Q75: 0 | R75: STOCKOUT | S75: WARNING | T75: STOCK-OUT EXPOSURE

Sheet RCA_Stockouts
A1: Root-cause analysis of stock-out events
A2: Source: sp_stockout_root_cause. One primary cause per event; precedence documented in the procedure header.
A4: primary_cause | B4: stockout_events | C4: lost_units | D4: lost_revenue_inr | E4: lost_margin_inr | F4: pct_of_lost_revenue
A5: 1 Planning policy gap (reorder point too low) | B5: 3171 | C5: 638164 | D5: 125676139 | E5: 25035076 | F5: 31.7
A6: 2 Supplier delay | B6: 2912 | C6: 802969 | D6: 153078514 | E6: 30183914 | F6: 38.6
A7: 3 Supplier short-shipment | B7: 221 | C7: 43627 | D7: 8379544 | E7: 1665856 | F7: 2.1
A8: 4 Unforecast demand spike | B8: 769 | C8: 153742 | D8: 49592869 | E8: 10426046 | F8: 12.5
A9: 5 Demand variability / thin safety stock | B9: 2105 | C9: 292167 | D9: 59341318 | E9: 11911789 | F9: 15
A10: TOTAL | B10: =SUM(B5:B9) | C10: =SUM(C5:C9) | D10: =SUM(D5:D9) | E10: =SUM(E5:E9) | F10: =SUM(F5:F9)
A12: Lost revenue (INR) by warehouse and primary cause
A13: warehouse_id | B13: warehouse_name | C13: region | D13: stockout_events | E13: policy_gap_inr | F13: supplier_delay_inr | G13: short_ship_inr | H13: demand_spike_inr | I13: variability_inr | J13: total_lost_revenue_inr
A14: WH08 | B14: Chennai DC | C14: South | D14: 2645 | E14: 94352169 | F14: 26762683 | G14: 1731043 | H14: 11466513 | I14: 9634612 | J14: 143947020
A15: WH11 | B15: Guwahati DC | C15: East | D15: 2132 | E15: 28604484 | F15: 14411670 | G15: 490657 | H15: 6042416 | I15: 9581113 | J15: 59130340
A16: WH10 | B16: Kolkata DC | C16: East | D16: 923 | E16: 806907 | F16: 23202847 | G16: 1958569 | H16: 6054607 | I16: 9031787 | J16: 41054717
A17: WH06 | B17: Ahmedabad DC | C17: West | D17: 574 | E17: 18642 | F17: 15913238 | G17: 532592 | H17: 11689260 | I17: 5802261 | J17: 33955993
A18: WH09 | B18: Hyderabad DC | C18: South | D18: 555 | E18: 41738 | F18: 20062588 | G18: 1592963 | H18: 3096270 | I18: 5768002 | J18: 30561561
A19: WH07 | B19: Bengaluru DC | C19: South | D19: 550 | E19: 1630828 | F19: 18950941 | G19: 240867 | H19: 3857572 | I19: 5377676 | J19: 30057884
A20: WH12 | B20: Nagpur DC | C20: Central | D20: 446 | E20: 3278 | F20: 8286779 | G20: 308010 | H20: 2052754 | I20: 3562672 | J20: 14213493
A21: WH03 | B21: Lucknow DC | C21: North | D21: 500 | E21: 218093 | F21: 7879854 | G21: 255094 | H21: 1506728 | I21: 4110883 | J21: 13970652
A22: WH02 | B22: Jaipur DC | C22: North | D22: 480 | E22: 0 | F22: 8703722 | G22: 922785 | H22: 1169906 | I22: 2288385 | J22: 13084798
A23: WH05 | B23: Pune DC | C23: West | D23: 339 | E23: 0 | F23: 6719402 | G23: 346964 | H23: 2159846 | I23: 2589645 | J23: 11815857
A24: WH04 | B24: Bhiwandi DC | C24: West | D24: 14 | E24: 0 | F24: 759913 | G24: 0 | H24: 495485 | I24: 1269402 | J24: 2524800
A25: WH01 | B25: Gurugram DC | C25: North | D25: 20 | E25: 0 | F25: 1424877 | G25: 0 | H25: 1512 | I25: 324880 | J25: 1751269
A26: TOTAL | D26: =SUM(D14:D25) | E26: =SUM(E14:E25) | F26: =SUM(F14:F25) | G26: =SUM(G14:G25) | H26: =SUM(H14:H25) | I26: =SUM(I14:I25) | J26: =SUM(J14:J25)
A29: How often each factor was present (events can have several)
A30: stockout_events | B30: pct_with_policy_gap | C30: pct_with_late_po | D30: pct_with_short_ship | E30: pct_with_demand_spike
A31: 9178 | B31: 34.6 | C31: 40.2 | D31: 6 | E31: 16.2

Sheet Excess_Inventory
A1: Excess and above-target inventory
A2: Source: sp_excess_inventory_waste. Above-target = stock beyond 4 weeks of cover; excess = beyond 8 weeks.
A4: warehouse_id | B4: warehouse_name | C4: region | D4: total_stock_value_inr | E4: excess_value_inr | F4: excess_pct_of_stock | G4: annual_carrying_cost_on_excess_inr | H4: above_target_cover_value_inr | I4: above_target_pct_of_stock | J4: annual_carrying_cost_above_target_inr | K4: obsolescence_risk_skus | L4: obsolescence_risk_value_inr | M4: expiry_risk_skus | N4: expiry_risk_value_inr
A5: WH04 | B5: Bhiwandi DC | C5: West | D5: 78119785 | E5: 6589930 | F5: 8.4 | G5: 1449785 | H5: 32089121 | I5: 41.1 | J5: 7059607 | K5: 0 | L5: 0 | M5: 5 | N5: 4510546
A6: WH01 | B6: Gurugram DC | C6: North | D6: 53413145 | E6: 3843427 | F6: 7.2 | G6: 845554 | H6: 21092465 | I6: 39.5 | J6: 4640342 | K6: 0 | L6: 0 | M6: 1 | N6: 115200
A7: WH12 | B7: Nagpur DC | C7: Central | D7: 10849035 | E7: 800147 | F7: 7.4 | G7: 176032 | H7: 1814046 | I7: 16.7 | J7: 399090 | K7: 0 | L7: 0 | M7: 3 | N7: 339648
A8: WH02 | B8: Jaipur DC | C8: North | D8: 12386634 | E8: 622305 | F8: 5 | G8: 136907 | H8: 1730856 | I8: 14 | J8: 380788 | K8: 2 | L8: 412538 | M8: 6 | N8: 889239
A9: WH03 | B9: Lucknow DC | C9: North | D9: 12746845 | E9: 616716 | F9: 4.8 | G9: 135678 | H9: 1753603 | I9: 13.8 | J9: 385793 | K9: 2 | L9: 264198 | M9: 2 | N9: 245964
A10: WH06 | B10: Ahmedabad DC | C10: West | D10: 14011100 | E10: 270638 | F10: 1.9 | G10: 59540 | H10: 1428177 | I10: 10.2 | J10: 314199 | K10: 0 | L10: 0 | M10: 0 | N10: 0
A11: WH11 | B11: Guwahati DC | C11: East | D11: 7118011 | E11: 230462 | F11: 3.2 | G11: 50702 | H11: 1089999 | I11: 15.3 | J11: 239800 | K11: 4 | L11: 167259 | M11: 4 | N11: 153764
A12: WH05 | B12: Pune DC | C12: West | D12: 17279062 | E12: 110817 | F12: 0.6 | G12: 24380 | H12: 2488211 | I12: 14.4 | J12: 547406 | K12: 0 | L12: 0 | M12: 1 | N12: 127185
A13: WH09 | B13: Hyderabad DC | C13: South | D13: 23416807 | E13: 79365 | F13: 0.3 | G13: 17460 | H13: 3251831 | I13: 13.9 | J13: 715403 | K13: 0 | L13: 0 | M13: 0 | N13: 0
A14: WH07 | B14: Bengaluru DC | C14: South | D14: 20767489 | E14: 31624 | F14: 0.2 | G14: 6957 | H14: 2144763 | I14: 10.3 | J14: 471848 | K14: 0 | L14: 0 | M14: 0 | N14: 0
A15: WH08 | B15: Chennai DC | C15: South | D15: 8162258 | E15: 23776 | F15: 0.3 | G15: 5231 | H15: 241115 | I15: 3 | J15: 53045 | K15: 0 | L15: 0 | M15: 0 | N15: 0
A16: WH10 | B16: Kolkata DC | C16: East | D16: 17145860 | E16: 15721 | F16: 0.1 | G16: 3459 | H16: 1591298 | I16: 9.3 | J16: 350086 | K16: 0 | L16: 0 | M16: 0 | N16: 0
A17: NETWORK | D17: =SUM(D5:D16) | E17: =SUM(E5:E16) | G17: =SUM(G5:G16) | H17: =SUM(H5:H16) | J17: =SUM(J5:J16) | K17: =SUM(K5:K16) | L17: =SUM(L5:L16) | M17: =SUM(M5:M16) | N17: =SUM(N5:N16)
A20: By category
A21: category | B21: total_stock_value_inr | C21: excess_value_inr | D21: excess_pct_of_stock | E21: annual_carrying_cost_on_excess_inr | F21: above_target_cover_value_inr | G21: expiry_risk_value_inr
A22: Electronics Accessories | B22: 82522130 | C22: 7174485 | D22: 8.7 | E22: 1578387 | F22: 28180450 | G22: 0
A23: Snacks & Confectionery | B23: 29704368 | C23: 1311456 | D23: 4.4 | E23: 288520 | F23: 6951415 | G23: 5453236
A24: Beverages | B24: 30381748 | C24: 1050331 | D24: 3.5 | E24: 231073 | F24: 6532208 | G24: 765011
A25: OTC Pharma & Wellness | B25: 17867042 | C25: 1007232 | D25: 5.6 | E25: 221591 | F25: 5122219 | G25: 66459
A26: Packaging & Supplies | B26: 19863981 | C26: 917482 | D26: 4.6 | E26: 201846 | F26: 5069697 | G26: 0
A27: Personal Care | B27: 25910925 | C27: 654928 | D27: 2.5 | E27: 144084 | F27: 5493938 | G27: 0
A28: Home Care | B28: 22772503 | C28: 565887 | D28: 2.5 | E28: 124495 | F28: 3975193 | G28: 0
A29: Packaged Staples | B29: 46393334 | C29: 553127 | D29: 1.2 | E29: 121688 | F29: 9390365 | G29: 96840

Sheet Rebalance
A1: Recommended stock transfers
A2: Source: sp_regional_rebalance. Indicative, one replenishment cycle; freight rates are assumptions (Config).
A4: sku_id | B4: sku_name | C4: category | D4: from_warehouse_id | E4: from_warehouse | F4: from_region | G4: to_warehouse_id | H4: to_warehouse | I4: to_region | J4: receiver_status | K4: transfer_units | L4: same_region | M4: stock_value_moved_inr | N4: est_freight_inr | O4: margin_protected_inr | P4: est_net_benefit_inr
A5: SKU080 | B5: TWS Earbuds | C5: Electronics Accessories | D5: WH01 | E5: Gurugram DC | F5: North | G5: WH06 | H5: Ahmedabad DC | I5: West | J5: STOCKOUT | K5: 995 | L5: 0 | M5: 2226810 | N5: 5970 | O5: 705455 | P5: 699485
A6: SKU080 | B6: TWS Earbuds | C6: Electronics Accessories | D6: WH01 | E6: Gurugram DC | F6: North | G6: WH08 | H6: Chennai DC | I6: South | J6: STOCKOUT | K6: 542 | L6: 0 | M6: 1212996 | N6: 3252 | O6: 384278 | P6: 381026
A7: SKU087 | B7: SD Card 64GB | C7: Electronics Accessories | D7: WH04 | E7: Bhiwandi DC | F7: West | G7: WH07 | H7: Bengaluru DC | I7: South | J7: LOW | K7: 526 | L7: 0 | M7: 920500 | N7: 3156 | O7: 226180 | P7: 223024
A8: SKU087 | B8: SD Card 64GB | C8: Electronics Accessories | D8: WH04 | E8: Bhiwandi DC | F8: West | G8: WH08 | H8: Chennai DC | I8: South | J8: LOW | K8: 464 | L8: 0 | M8: 812000 | N8: 2784 | O8: 199520 | P8: 196736
A9: SKU079 | B9: Wired Earphones | C9: Electronics Accessories | D9: WH01 | E9: Gurugram DC | F9: North | G9: WH08 | H9: Chennai DC | I9: South | J9: STOCKOUT | K9: 653 | L9: 0 | M9: 724830 | N9: 3918 | O9: 197206 | P9: 193288
A10: SKU087 | B10: SD Card 64GB | C10: Electronics Accessories | D10: WH04 | E10: Bhiwandi DC | F10: West | G10: WH11 | H10: Guwahati DC | I10: East | J10: STOCKOUT | K10: 273 | L10: 0 | M10: 477750 | N10: 1638 | O10: 117390 | P10: 115752
A11: SKU079 | B11: Wired Earphones | C11: Electronics Accessories | D11: WH01 | E11: Gurugram DC | F11: North | G11: WH11 | H11: Guwahati DC | I11: East | J11: STOCKOUT | K11: 375 | L11: 0 | M11: 416250 | N11: 2250 | O11: 113250 | P11: 111000
A12: SKU111 | B12: Shipping Labels 1000 | C12: Packaging & Supplies | D12: WH04 | E12: Bhiwandi DC | F12: West | G12: WH08 | H12: Chennai DC | I12: South | J12: STOCKOUT | K12: 726 | L12: 0 | M12: 447942 | N12: 4356 | O12: 90024 | P12: 85668
A13: SKU060 | B13: Mouthwash 250ml | C13: Personal Care | D13: WH12 | E13: Nagpur DC | F13: Central | G13: WH06 | H13: Ahmedabad DC | I13: West | J13: LOW | K13: 783 | L13: 0 | M13: 294408 | N13: 4698 | O13: 90045 | P13: 85347
A14: SKU082 | B14: Phone Case | C14: Electronics Accessories | D14: WH04 | E14: Bhiwandi DC | F14: West | G14: WH07 | H14: Bengaluru DC | I14: South | J14: CRITICAL | K14: 449 | L14: 0 | M14: 298585 | N14: 2694 | O14: 76330 | P14: 73636
A15: SKU086 | B15: AA Batteries 10pk | C15: Electronics Accessories | D15: WH01 | E15: Gurugram DC | F15: North | G15: WH02 | H15: Jaipur DC | I15: North | J15: LOW | K15: 177 | L15: 1 | M15: 236295 | N15: 443 | O15: 71685 | P15: 71243
A16: SKU089 | B16: USB Keyboard | C16: Electronics Accessories | D16: WH01 | E16: Gurugram DC | F16: North | G16: WH07 | H16: Bengaluru DC | I16: South | J16: STOCKOUT | K16: 116 | L16: 0 | M16: 260884 | N16: 696 | O16: 65308 | P16: 64612
... A240: SKU035 | B240: Chocolate Bar 40g | C240: Snacks & Confectionery | D240: WH04 | E240: Bhiwandi DC | F240: West | G240: WH08 | H240: Chennai DC | I240: South | J240: LOW | K240: 2269 | L240: 0 | M240: 36304 | N240: 13614 | O240: 9076 | P240: -4538
A241: TOTAL | K241: =SUM(K5:K240) | M241: =SUM(M5:M240) | N241: =SUM(N5:N240) | O241: =SUM(O5:O240) | P241: =SUM(P5:P240)

Sheet Asset_RCA
A1: Asset waste root-cause analysis (Oct-2024 to Sep-2026)
A2: Source: sp_asset_waste_rca. surplus_assets > 0 = over-provisioned; < 0 = shortfall.
A4: warehouse_id | B4: warehouse_name | C4: region | D4: assets | E4: utilisation_pct | F4: idle_pct | G4: downtime_pct | H4: breakdowns | I4: maintenance_cost_inr | J4: idle_cost_inr | K4: net_surplus_assets
A5: WH05 | B5: Pune DC | C5: West | D5: 41 | E5: 35.5 | F5: 60.5 | G5: 4 | H5: 695 | I5: 32331783 | J5: 16232912 | K5: 20
A6: WH02 | B6: Jaipur DC | C6: North | D6: 23 | E6: 40.9 | F6: 54.2 | G6: 4.8 | H6: 499 | I6: 21055387 | J6: 8283572 | K6: 10
A7: WH04 | B7: Bhiwandi DC | C7: West | D7: 41 | E7: 70.7 | F7: 24.6 | G7: 4.7 | H7: 782 | I7: 34600578 | J7: 6632178 | K7: 0
A8: WH07 | B8: Bengaluru DC | C8: South | D8: 33 | E8: 69.3 | F8: 26.3 | G8: 4.4 | H8: 565 | I8: 25346191 | J8: 5613195 | K8: 0
A9: WH09 | B9: Hyderabad DC | C9: South | D9: 27 | E9: 71.7 | F9: 23.7 | G9: 4.6 | H9: 505 | I9: 23061818 | J9: 4460277 | K9: 0
A10: WH01 | B10: Gurugram DC | C10: North | D10: 27 | E10: 73.3 | F10: 22.1 | G10: 4.6 | H10: 523 | I10: 22301448 | J10: 4090603 | K10: 0
A11: WH10 | B11: Kolkata DC | C11: East | D11: 26 | E11: 68.4 | F11: 22.9 | G11: 8.8 | H11: 1032 | I11: 41121117 | J11: 3871535 | K11: 0
A12: WH06 | B12: Ahmedabad DC | C12: West | D12: 23 | E12: 70 | F12: 26 | G12: 3.9 | H12: 334 | I12: 15310732 | J12: 3783951 | K12: 0
A13: WH03 | B13: Lucknow DC | C13: North | D13: 16 | E13: 68.8 | F13: 23.1 | G13: 8.1 | H13: 553 | I13: 21998147 | J13: 2298009 | K13: 0
A14: WH12 | B14: Nagpur DC | C14: Central | D14: 13 | E14: 68.1 | F14: 27 | G14: 4.9 | H14: 250 | I14: 11332274 | J14: 2184267 | K14: 0
A15: WH11 | B15: Guwahati DC | C15: East | D15: 7 | E15: 83.4 | F15: 11.2 | G15: 5.3 | H15: 179 | I15: 8772577 | J15: 502713 | K15: -1
A16: WH08 | B16: Chennai DC | C16: South | D16: 14 | E16: 93.1 | F16: 0.5 | G16: 6.4 | H16: 431 | I16: 17932158 | J16: 77079 | K16: -4
A17: NETWORK | D17: =SUM(D5:D16) | H17: =SUM(H5:H16) | I17: =SUM(I5:I16) | J17: =SUM(J5:J16) | K17: =SUM(K5:K16)
A20: Detail by warehouse and asset type
A21: warehouse_id | B21: warehouse_name | C21: region | D21: asset_type | E21: asset_count | F21: avg_age_years | G21: utilisation_pct | H21: idle_pct | I21: downtime_pct | J21: breakdowns | K21: maintenance_cost_inr | L21: maintenance_cost_per_run_hour_inr | M21: idle_cost_inr | N21: surplus_assets | O21: diagnosis
A22: WH01 | B22: Gurugram DC | C22: North | D22: Conveyor Line | E22: 2 | F22: 2.4 | G22: 85.3 | H22: 11.5 | I22: 3.1 | J22: 18 | K22: 1624772 | L22: 79.3 | M22: 115651 | N22: 0 | O22: OK
A23: WH01 | B23: Gurugram DC | C23: North | D23: Delivery Truck | E23: 7 | F23: 5.9 | G23: 69.4 | H23: 25.6 | I23: 5 | J23: 143 | K23: 7841431 | L23: 224.2 | M23: 1606866 | N23: 0 | O23: OK
A24: WH01 | B24: Gurugram DC | C24: North | D24: Electric Pallet Jack | E24: 8 | F24: 4.9 | G24: 72.7 | H24: 22.9 | I24: 4.4 | J24: 152 | K24: 2405801 | L24: 43.1 | M24: 641913 | N24: 0 | O24: OK
A25: WH01 | B25: Gurugram DC | C25: North | D25: Forklift (Electric) | E25: 6 | F25: 6.1 | G25: 72.8 | H25: 22 | I25: 5.2 | J25: 138 | K25: 5533554 | L25: 132 | M25: 837573 | N25: 0 | O25: OK
A26: WH01 | B26: Gurugram DC | C26: North | D26: Reach Truck | E26: 4 | F26: 5 | G26: 72.9 | H26: 22.7 | I26: 4.4 | J26: 72 | K26: 4895890 | L26: 175 | M26: 888600 | N26: 0 | O26: OK
A27: WH02 | B27: Jaipur DC | C27: North | D27: Conveyor Line | E27: 2 | F27: 3.7 | G27: 41.9 | H27: 54.4 | I27: 3.6 | J27: 28 | K27: 2315655 | L27: 230.1 | M27: 679771 | N27: 1 | O27: OVER-PROVISIONED (idle capacity)
A28: WH02 | B28: Jaipur DC | C28: North | D28: Delivery Truck | E28: 6 | F28: 5 | G28: 38.6 | H28: 56.9 | I28: 4.5 | J28: 120 | K28: 6825987 | L28: 409.9 | M28: 3179074 | N28: 3 | O28: OVER-PROVISIONED (idle capacity)
A29: WH02 | B29: Jaipur DC | C29: North | D29: Electric Pallet Jack | E29: 7 | F29: 5.2 | G29: 39.5 | H29: 55.9 | I29: 4.6 | J29: 149 | K29: 2212594 | L29: 83.3 | M29: 1384735 | N29: 3 | O29: OVER-PROVISIONED (idle capacity)
A30: WH02 | B30: Jaipur DC | C30: North | D30: Forklift (Electric) | E30: 5 | F30: 7.1 | G30: 41.7 | H30: 52.7 | I30: 5.6 | J30: 135 | K30: 5268378 | L30: 263.4 | M30: 1597765 | N30: 2 | O30: OVER-PROVISIONED (idle capacity)
A31: WH02 | B31: Jaipur DC | C31: North | D31: Reach Truck | E31: 3 | F31: 7.3 | G31: 45.8 | H31: 48.5 | I31: 5.7 | J31: 67 | K31: 4432773 | L31: 336.4 | M31: 1442227 | N31: 1 | O31: OVER-PROVISIONED (idle capacity)
A32: WH03 | B32: Lucknow DC | C32: North | D32: Conveyor Line | E32: 1 | F32: 10.2 | G32: 88.8 | H32: 3.1 | I32: 8.1 | J32: 33 | K32: 2198833 | L32: 206.4 | M32: 19484 | N32: 0 | O32: RELIABILITY (ageing / breakdowns)
A33: WH03 | B33: Lucknow DC | C33: North | D33: Delivery Truck | E33: 4 | F33: 11.4 | G33: 68.4 | H33: 23.3 | I33: 8.3 | J33: 152 | K33: 7862194 | L33: 399.1 | M33: 802589 | N33: 0 | O33: RELIABILITY (ageing / breakdowns)
... A81: WH12 | B81: Nagpur DC | C81: Central | D81: Reach Truck | E81: 2 | F81: 5.5 | G81: 65.1 | H81: 30.2 | I81: 4.7 | J81: 33 | K81: 2334387 | L81: 186.8 | M81: 555496 | N81: 0 | O81: OK
